Workbook

Sheet Riepilogo
A1: Rendicontazione Assistenza Specialistica
A2: Comune di Napoli · Assistenza Specialistica all'integrazione scolastica · Febbraio – Marzo 2026 · COOPERATIVA SOCIALE SIRIO
A4: Generato il 10/10/2026 alle 17:01 con Sirio OCR 1.0.0 · 4 fogli firma
A5: FOGLI FIRMA | C5: ORE RICONOSCIUTE | E5: ORE PROGRAMMATE | H5: GIORNI LAVORATI | K5: ASSENZE ALUNNO | O5: ASSENZE OPERATORE | S5: CAMPI ILLEGGIBILI | V5: ANOMALIE DA ESAMINARE
A6: =SUBTOTAL(103,$B$12:$B$15) -> 4 | C6: =$J$16 -> 208.25 | E6: =$G$16 -> 218 | H6: =$M$16 -> 78 | K6: =$N$16 -> 2 | O6: =$O$16 -> 1 | S6: =$R$16 -> 1 | V6: =$S$16+$T$16 -> 11
A7: =COUNTIF($V$12:$V$15,"Sì")&IF(COUNTIF($V$12:$V$15,"Sì")=1," verificato"," verificati")&" · "&COUNTIF($U$12:$U$15,"Errori")&" con errori" -> 1 verificato · 2 con errori | C7: ore effettive ammesse | E7: da orario programmato | H7: giornate con ore riconosciute | K7: giornate | O7: giornate | S7: ="più "&$Q$16&IF($Q$16=1," lettura incerta"," letture incerte") -> più 4 letture incerte | V7: =$S$16&IF($S$16=1," errore"," errori")&" · "&$T$16&IF($T$16=1," attenzione"," attenzioni") -> 3 errori · 8 attenzioni
A9: Da verificare sugli originali: 1 campo illeggibile e 4 letture incerte. Le celle sono evidenziate in rosso (illeggibile) e in ambra (incerto) nelle schede dei fogli firma e nel Dettaglio giornaliero; l'elenco completo è nel foglio Anomalie.
A11: N. | B11: Operatore | C11: Alunno | D11: Istituto | E11: Mese | F11: Ore PEI sett. | G11: Ore programmate | H11: Ore calcolate | I11: Ore dichiarate | J11: Ore riconosciute | K11: Totale mensile dichiarato | L11: Differenza totale | M11: Giorni lavorati | N11: Assenze alunno | O11: Assenze operatore | P11: Firme mancanti | Q11: Campi incerti | R11: Campi illeggibili | S11: Errori | T11: Attenzioni | U11: Stato | V11: Verificato | W11: File di origine
A12: 1 | B12: DE LUCA GIOVANNA | C12: NERI MATTEO | D12: IC 12 VITTORIO EMANUELE | E12: 46082 | F12: 10 | G12: ='DE LUCA G. 03-2026'!$M$45 -> 44 | H12: ='DE LUCA G. 03-2026'!$N$45 -> 46.25 | I12: ='DE LUCA G. 03-2026'!$H$45 -> 46.25 | J12: ='DE LUCA G. 03-2026'!$O$45 -> 46.25 | K12: =IF(ISBLANK('DE LUCA G. 03-2026'!$H$48),"",'DE LUCA G. 03-2026'!$H$48) -> 46.25 | L12: =IF(ISNUMBER(K12),I12-K12,"") -> 0 | M12: ='DE LUCA G. 03-2026'!$H$55 -> 23 | N12: ='DE LUCA G. 03-2026'!$I$45 -> 0 | O12: ='DE LUCA G. 03-2026'!$J$45 -> 0 | P12: 0 | Q12: 1 | R12: 0 | S12: 0 | T12: 4 | U12: Da verificare | V12: No | W12: de_luca_marzo.pdf
A13: 2 | B13: ESPOSITO ANNA | C13: VERDI SOFIA | D13: IC 47 SARRIA-MONTI | E13: 46054 | F13: 12 | G13: ='ESPOSITO A. 02-2026'!$M$45 -> 48 | H13: ='ESPOSITO A. 02-2026'!$N$45 -> 45 | I13: ='ESPOSITO A. 02-2026'!$H$45 -> 45 | J13: ='ESPOSITO A. 02-2026'!$O$45 -> 45 | K13: =IF(ISBLANK('ESPOSITO A. 02-2026'!$H$48),"",'ESPOSITO A. 02-2026'!$H$48) -> 45 | L13: =IF(ISNUMBER(K13),I13-K13,"") -> 0 | M13: ='ESPOSITO A. 02-2026'!$H$55 -> 15 | N13: ='ESPOSITO A. 02-2026'!$I$45 -> 0 | O13: ='ESPOSITO A. 02-2026'!$J$45 -> 1 | P13: 0 | Q13: 0 | R13: 0 | S13: 0 | T13: 0 | U13: OK | V13: Sì | W13: fogli_firma_febbraio.pdf · pag. 2
A14: 3 | B14: ROSSI MARIO | C14: BIANCHI LUCA | D14: IC 12 VITTORIO EMANUELE | E14: 46054 | F14: 15 | G14: ='ROSSI M. 02-2026'!$M$45 -> 60 | H14: ='ROSSI M. 02-2026'!$N$45 -> 48 | I14: ='ROSSI M. 02-2026'!$H$45 -> 52.5 | J14: ='ROSSI M. 02-2026'!$O$45 -> 52.5 | K14: =IF(ISBLANK('ROSSI M. 02-2026'!$H$48),"",'ROSSI M. 02-2026'!$H$48) -> 52.5 | L14: =IF(ISNUMBER(K14),I14-K14,"") -> 0 | M14: ='ROSSI M. 02-2026'!$H$55 -> 18 | N14: ='ROSSI M. 02-2026'!$I$45 -> 1 | O14: ='ROSSI M. 02-2026'!$J$45 -> 0 | P14: 0 | Q14: 2 | R14: 1 | S14: 1 | T14: 2 | U14: Errori | V14: No | W14: fogli_firma_febbraio.pdf · pag. 1
A15: 4 | B15: ROSSI MARIO | C15: BIANCHI LUCA | D15: IC 12 VITTORIO EMANUELE | E15: 46082 | F15: 15 | G15: ='ROSSI M. 03-2026'!$M$45 -> 66 | H15: ='ROSSI M. 03-2026'!$N$45 -> 62.5 | I15: ='ROSSI M. 03-2026'!$H$45 -> 64.5 | J15: ='ROSSI M. 03-2026'!$O$45 -> 64.5 | K15: =IF(ISBLANK('ROSSI M. 03-2026'!$H$48),"",'ROSSI M. 03-2026'!$H$48) -> 64 | L15: =IF(ISNUMBER(K15),I15-K15,"") -> 0.5 | M15: ='ROSSI M. 03-2026'!$H$55 -> 22 | N15: ='ROSSI M. 03-2026'!$I$45 -> 1 | O15: ='ROSSI M. 03-2026'!$J$45 -> 0 | P15: 1 | Q15: 1 | R15: 0 | S15: 2 | T15: 2 | U15: Errori | V15: No | W15: rossi_marzo.pdf
B16: Totale | C16: =SUBTOTAL(103,$B$12:$B$15)&" fogli firma" -> 4 fogli firma | G16: =SUBTOTAL(109,$G$12:$G$15) -> 218 | H16: =SUBTOTAL(109,$H$12:$H$15) -> 201.75 | I16: =SUBTOTAL(109,$I$12:$I$15) -> 208.25 | J16: =SUBTOTAL(109,$J$12:$J$15) -> 208.25 | K16: =SUBTOTAL(109,$K$12:$K$15) -> 207.75 | L16: =SUBTOTAL(109,$L$12:$L$15) -> 0.5 | M16: =SUBTOTAL(109,$M$12:$M$15) -> 78 | N16: =SUBTOTAL(109,$N$12:$N$15) -> 2 | O16: =SUBTOTAL(109,$O$12:$O$15) -> 1 | P16: =SUBTOTAL(109,$P$12:$P$15) -> 1 | Q16: =SUBTOTAL(109,$Q$12:$Q$15) -> 4 | R16: =SUBTOTAL(109,$R$12:$R$15) -> 1 | S16: =SUBTOTAL(109,$S$12:$S$15) -> 3 | T16: =SUBTOTAL(109,$T$12:$T$15) -> 8
A18: Fare clic sul nome dell'operatore per aprire la scheda del foglio firma. Le colonne in blu sono calcolate con formule; i totali considerano solo le righe visibili quando si usano i filtri.
A19: Stato: «Errori» = almeno un controllo non superato; «Da verificare» = segnalazioni o campi incerti/illeggibili; «OK» = nessun rilievo. Il significato dei colori e le regole di calcolo sono nel foglio «Legenda e note».

Sheet Dettaglio giornaliero
A1: Dettaglio giornaliero
A2: Febbraio – Marzo 2026 · una riga per ogni giornata con dati · ore in formato decimale (1,50 = un'ora e mezza)
A4: Totale delle righe visibili | M4: =SUBTOTAL(109,$M$6:$M$86) -> 218 | N4: =SUBTOTAL(109,$N$6:$N$86) -> 201.75 | O4: =SUBTOTAL(109,$O$6:$O$86) -> 208.25 | P4: =SUBTOTAL(109,$P$6:$P$86) -> 208.25 | V4: =SUBTOTAL(103,$A$6:$A$86)&" giornate visibili" -> 81 giornate visibili
A5: Doc. | B5: Operatore | C5: Alunno | D5: Istituto | E5: Mese | F5: Data | G5: Giorno | H5: Tipo giorno | I5: Entrata progr. | J5: Uscita progr. | K5: Entrata eff. | L5: Uscita eff. | M5: Ore progr. | N5: Ore calcolate | O5: Ore dichiarate | P5: Ore riconosciute | Q5: Differenza | R5: Assenza alunno | S5: Assenza operatore | T5: Firma | U5: Note | V5: Esito | W5: Anomalie del giorno
A6: 1 | B6: DE LUCA GIOVANNA | C6: NERI MATTEO | D6: IC 12 VITTORIO EMANUELE | E6: 46082 | F6: 46083 | G6: lun | H6: Feriale | I6: 0.375 | J6: 0.45833333 | K6: 0.375 | L6: 0.45833333 | M6: =IF(AND(ISNUMBER(I6),ISNUMBER(J6)),IF(J6>I6,(J6-I6)*24,""),"") -> 2 | N6: =IF(AND(ISNUMBER(K6),ISNUMBER(L6)),IF(L6>K6,(L6-K6)*24,""),"") -> 2 | O6: 2 | P6: =IF(S6="Sì",0,IF(ISNUMBER(O6),O6,IF(ISNUMBER(N6),N6,""))) -> 2 | Q6: =IF(AND(ISNUMBER(O6),ISNUMBER(N6)),O6-N6,"") -> 0 | T6: Sì | V6: OK
A7: 1 | B7: DE LUCA GIOVANNA | C7: NERI MATTEO | D7: IC 12 VITTORIO EMANUELE | E7: 46082 | F7: 46084 | G7: mar | H7: Feriale | I7: 0.375 | J7: 0.45833333 | K7: 0.375 | L7: 0.45833333 | M7: =IF(AND(ISNUMBER(I7),ISNUMBER(J7)),IF(J7>I7,(J7-I7)*24,""),"") -> 2 | N7: =IF(AND(ISNUMBER(K7),ISNUMBER(L7)),IF(L7>K7,(L7-K7)*24,""),"") -> 2 | O7: 2 | P7: =IF(S7="Sì",0,IF(ISNUMBER(O7),O7,IF(ISNUMBER(N7),N7,""))) -> 2 | Q7: =IF(AND(ISNUMBER(O7),ISNUMBER(N7)),O7-N7,"") -> 0 | T7: Sì | V7: OK
A8: 1 | B8: DE LUCA GIOVANNA | C8: NERI MATTEO | D8: IC 12 VITTORIO EMANUELE | E8: 46082 | F8: 46085 | G8: mer | H8: Feriale | I8: 0.375 | J8: 0.45833333 | K8: 0.375 | L8: 0.45833333 | M8: =IF(AND(ISNUMBER(I8),ISNUMBER(J8)),IF(J8>I8,(J8-I8)*24,""),"") -> 2 | N8: =IF(AND(ISNUMBER(K8),ISNUMBER(L8)),IF(L8>K8,(L8-K8)*24,""),"") -> 2 | O8: 2 | P8: =IF(S8="Sì",0,IF(ISNUMBER(O8),O8,IF(ISNUMBER(N8),N8,""))) -> 2 | Q8: =IF(AND(ISNUMBER(O8),ISNUMBER(N8)),O8-N8,"") -> 0 | T8: Sì | V8: OK
A9: 1 | B9: DE LUCA GIOVANNA | C9: NERI MATTEO | D9: IC 12 VITTORIO EMANUELE | E9: 46082 | F9: 46086 | G9: gio | H9: Feriale | I9: 0.375 | J9: 0.45833333 | K9: 0.375 | L9: 0.45833333 | M9: =IF(AND(ISNUMBER(I9),ISNUMBER(J9)),IF(J9>I9,(J9-I9)*24,""),"") -> 2 | N9: =IF(AND(ISNUMBER(K9),ISNUMBER(L9)),IF(L9>K9,(L9-K9)*24,""),"") -> 2 | O9: 2 | P9: =IF(S9="Sì",0,IF(ISNUMBER(O9),O9,IF(ISNUMBER(N9),N9,""))) -> 2 | Q9: =IF(AND(ISNUMBER(O9),ISNUMBER(N9)),O9-N9,"") -> 0 | T9: Sì | V9: OK
A10: 1 | B10: DE LUCA GIOVANNA | C10: NERI MATTEO | D10: IC 12 VITTORIO EMANUELE | E10: 46082 | F10: 46087 | G10: ven | H10: Feriale | I10: 0.375 | J10: 0.45833333 | K10: 0.375 | L10: 0.45833333 | M10: =IF(AND(ISNUMBER(I10),ISNUMBER(J10)),IF(J10>I10,(J10-I10)*24,""),"") -> 2 | N10: =IF(AND(ISNUMBER(K10),ISNUMBER(L10)),IF(L10>K10,(L10-K10)*24,""),"") -> 2 | O10: 2 | P10: =IF(S10="Sì",0,IF(ISNUMBER(O10),O10,IF(ISNUMBER(N10),N10,""))) -> 2 | Q10: =IF(AND(ISNUMBER(O10),ISNUMBER(N10)),O10-N10,"") -> 0 | T10: Sì | V10: OK
A11: 1 | B11: DE LUCA GIOVANNA | C11: NERI MATTEO | D11: IC 12 VITTORIO EMANUELE | E11: 46082 | F11: 46090 | G11: lun | H11: Feriale | I11: 0.375 | J11: 0.45833333 | K11: 0.375 | L11: 0.45833333 | M11: =IF(AND(ISNUMBER(I11),ISNUMBER(J11)),IF(J11>I11,(J11-I11)*24,""),"") -> 2 | N11: =IF(AND(ISNUMBER(K11),ISNUMBER(L11)),IF(L11>K11,(L11-K11)*24,""),"") -> 2 | O11: 2 | P11: =IF(S11="Sì",0,IF(ISNUMBER(O11),O11,IF(ISNUMBER(N11),N11,""))) -> 2 | Q11: =IF(AND(ISNUMBER(O11),ISNUMBER(N11)),O11-N11,"") -> 0 | T11: Sì | V11: OK
A12: 1 | B12: DE LUCA GIOVANNA | C12: NERI MATTEO | D12: IC 12 VITTORIO EMANUELE | E12: 46082 | F12: 46091 | G12: mar | H12: Feriale | I12: 0.375 | J12: 0.45833333 | K12: 0.375 | L12: 0.45833333 | M12: =IF(AND(ISNUMBER(I12),ISNUMBER(J12)),IF(J12>I12,(J12-I12)*24,""),"") -> 2 | N12: =IF(AND(ISNUMBER(K12),ISNUMBER(L12)),IF(L12>K12,(L12-K12)*24,""),"") -> 2 | O12: 2 | P12: =IF(S12="Sì",0,IF(ISNUMBER(O12),O12,IF(ISNUMBER(N12),N12,""))) -> 2 | Q12: =IF(AND(ISNUMBER(O12),ISNUMBER(N12)),O12-N12,"") -> 0 | T12: Sì | V12: OK
A13: 1 | B13: DE LUCA GIOVANNA | C13: NERI MATTEO | D13: IC 12 VITTORIO EMANUELE | E13: 46082 | F13: 46092 | G13: mer | H13: Feriale | I13: 0.375 | J13: 0.45833333 | K13: 0.375 | L13: 0.45833333 | M13: =IF(AND(ISNUMBER(I13),ISNUMBER(J13)),IF(J13>I13,(J13-I13)*24,""),"") -> 2 | N13: =IF(AND(ISNUMBER(K13),ISNUMBER(L13)),IF(L13>K13,(L13-K13)*24,""),"") -> 2 | O13: 2 | P13: =IF(S13="Sì",0,IF(ISNUMBER(O13),O13,IF(ISNUMBER(N13),N13,""))) -> 2 | Q13: =IF(AND(ISNUMBER(O13),ISNUMBER(N13)),O13-N13,"") -> 0 | T13: Sì | V13: OK
A14: 1 | B14: DE LUCA GIOVANNA | C14: NERI MATTEO | D14: IC 12 VITTORIO EMANUELE | E14: 46082 | F14: 46093 | G14: gio | H14: Feriale | I14: 0.375 | J14: 0.45833333 | K14: 0.375 | L14: 0.45833333 | M14: =IF(AND(ISNUMBER(I14),ISNUMBER(J14)),IF(J14>I14,(J14-I14)*24,""),"") -> 2 | N14: =IF(AND(ISNUMBER(K14),ISNUMBER(L14)),IF(L14>K14,(L14-K14)*24,""),"") -> 2 | O14: 2 | P14: =IF(S14="Sì",0,IF(ISNUMBER(O14),O14,IF(ISNUMBER(N14),N14,""))) -> 2 | Q14: =IF(AND(ISNUMBER(O14),ISNUMBER(N14)),O14-N14,"") -> 0 | T14: Sì | V14: OK
A15: 1 | B15: DE LUCA GIOVANNA | C15: NERI MATTEO | D15: IC 12 VITTORIO EMANUELE | E15: 46082 | F15: 46094 | G15: ven | H15: Feriale | I15: 0.375 | J15: 0.45833333 | K15: 0.375 | L15: 0.45833333 | M15: =IF(AND(ISNUMBER(I15),ISNUMBER(J15)),IF(J15>I15,(J15-I15)*24,""),"") -> 2 | N15: =IF(AND(ISNUMBER(K15),ISNUMBER(L15)),IF(L15>K15,(L15-K15)*24,""),"") -> 2 | O15: 2 | P15: =IF(S15="Sì",0,IF(ISNUMBER(O15),O15,IF(ISNUMBER(N15),N15,""))) -> 2 | Q15: =IF(AND(ISNUMBER(O15),ISNUMBER(N15)),O15-N15,"") -> 0 | T15: Sì | V15: OK
A16: 1 | B16: DE LUCA GIOVANNA | C16: NERI MATTEO | D16: IC 12 VITTORIO EMANUELE | E16: 46082 | F16: 46095 | G16: sab | H16: Sabato | K16: 0.375 | L16: 0.45833333 | M16: =IF(AND(ISNUMBER(I16),ISNUMBER(J16)),IF(J16>I16,(J16-I16)*24,""),"") | N16: =IF(AND(ISNUMBER(K16),ISNUMBER(L16)),IF(L16>K16,(L16-K16)*24,""),"") -> 2 | O16: 2 | P16: =IF(S16="Sì",0,IF(ISNUMBER(O16),O16,IF(ISNUMBER(N16),N16,""))) -> 2 | Q16: =IF(AND(ISNUMBER(O16),ISNUMBER(N16)),O16-N16,"") -> 0 | T16: Sì | U16: RECUPERO | V16: OK | W16: Prestazione registrata di sabato; verificare che sia prevista dal calendario scolastico. • Orario effettivo 09:00–11:00 senza orario programmato.
A17: 1 | B17: DE LUCA GIOVANNA | C17: NERI MATTEO | D17: IC 12 VITTORIO EMANUELE | E17: 46082 | F17: 46097 | G17: lun | H17: Feriale | I17: 0.375 | J17: 0.45833333 | K17: 0.375 | L17: 0.45833333 | M17: =IF(AND(ISNUMBER(I17),ISNUMBER(J17)),IF(J17>I17,(J17-I17)*24,""),"") -> 2 | N17: =IF(AND(ISNUMBER(K17),ISNUMBER(L17)),IF(L17>K17,(L17-K17)*24,""),"") -> 2 | O17: 2 | P17: =IF(S17="Sì",0,IF(ISNUMBER(O17),O17,IF(ISNUMBER(N17),N17,""))) -> 2 | Q17: =IF(AND(ISNUMBER(O17),ISNUMBER(N17)),O17-N17,"") -> 0 | T17: Sì | V17: OK
A18: 1 | B18: DE LUCA GIOVANNA | C18: NERI MATTEO | D18: IC 12 VITTORIO EMANUELE | E18: 46082 | F18: 46098 | G18: mar | H18: Feriale | I18: 0.375 | J18: 0.45833333 | K18: 0.375 | L18: 0.45833333 | M18: =IF(AND(ISNUMBER(I18),ISNUMBER(J18)),IF(J18>I18,(J18-I18)*24,""),"") -> 2 | N18: =IF(AND(ISNUMBER(K18),ISNUMBER(L18)),IF(L18>K18,(L18-K18)*24,""),"") -> 2 | O18: 2 | P18: =IF(S18="Sì",0,IF(ISNUMBER(O18),O18,IF(ISNUMBER(N18),N18,""))) -> 2 | Q18: =IF(AND(ISNUMBER(O18),ISNUMBER(N18)),O18-N18,"") -> 0 | T18: Sì | V18: OK
A19: 1 | B19: DE LUCA GIOVANNA | C19: NERI MATTEO | D19: IC 12 VITTORIO EMANUELE | E19: 46082 | F19: 46099 | G19: mer | H19: Feriale | I19: 0.375 | J19: 0.45833333 | K19: 0.375 | L19: 0.45833333 | M19: =IF(AND(ISNUMBER(I19),ISNUMBER(J19)),IF(J19>I19,(J19-I19)*24,""),"") -> 2 | N19: =IF(AND(ISNUMBER(K19),ISNUMBER(L19)),IF(L19>K19,(L19-K19)*24,""),"") -> 2 | O19: 2 | P19: =IF(S19="Sì",0,IF(ISNUMBER(O19),O19,IF(ISNUMBER(N19),N19,""))) -> 2 | Q19: =IF(AND(ISNUMBER(O19),ISNUMBER(N19)),O19-N19,"") -> 0 | T19: Sì | V19: OK
A20: 1 | B20: DE LUCA GIOVANNA | C20: NERI MATTEO | D20: IC 12 VITTORIO EMANUELE | E20: 46082 | F20: 46100 | G20: gio | H20: Feriale | I20: 0.375 | J20: 0.45833333 | K20: 0.375 | L20: 0.45833333 | M20: =IF(AND(ISNUMBER(I20),ISNUMBER(J20)),IF(J20>I20,(J20-I20)*24,""),"") -> 2 | N20: =IF(AND(ISNUMBER(K20),ISNUMBER(L20)),IF(L20>K20,(L20-K20)*24,""),"") -> 2 | O20: 2 | P20: =IF(S20="Sì",0,IF(ISNUMBER(O20),O20,IF(ISNUMBER(N20),N20,""))) -> 2 | Q20: =IF(AND(ISNUMBER(O20),ISNUMBER(N20)),O20-N20,"") -> 0 | T20: Sì | V20: OK
A21: 1 | B21: DE LUCA GIOVANNA | C21: NERI MATTEO | D21: IC 12 VITTORIO EMANUELE | E21: 46082 | F21: 46101 | G21: ven | H21: Feriale | I21: 0.375 | J21: 0.45833333 | K21: 0.375 | L21: 0.46875 | M21: =IF(AND(ISNUMBER(I21),ISNUMBER(J21)),IF(J21>I21,(J21-I21)*24,""),"") -> 2 | N21: =IF(AND(ISNUMBER(K21),ISNUMBER(L21)),IF(L21>K21,(L21-K21)*24,""),"") -> 2.25 | O21: 2.25 | P21: =IF(S21="Sì",0,IF(ISNUMBER(O21),O21,IF(ISNUMBER(N21),N21,""))) -> 2.25 | Q21: =IF(AND(ISNUMBER(O21),ISNUMBER(N21)),O21-N21,"") -> 0 | T21: Sì | V21: OK | W21: Orario effettivo 09:00–11:15 diverso dal programmato 09:00–11:00.
A22: 1 | B22: DE LUCA GIOVANNA | C22: NERI MATTEO | D22: IC 12 VITTORIO EMANUELE | E22: 46082 | F22: 46104 | G22: lun | H22: Feriale | I22: 0.375 | J22: 0.45833333 | K22: 0.375 | L22: 0.45833333 | M22: =IF(AND(ISNUMBER(I22),ISNUMBER(J22)),IF(J22>I22,(J22-I22)*24,""),"") -> 2 | N22: =IF(AND(ISNUMBER(K22),ISNUMBER(L22)),IF(L22>K22,(L22-K22)*24,""),"") -> 2 | O22: 2 | P22: =IF(S22="Sì",0,IF(ISNUMBER(O22),O22,IF(ISNUMBER(N22),N22,""))) -> 2 | Q22: =IF(AND(ISNUMBER(O22),ISNUMBER(N22)),O22-N22,"") -> 0 | T22: Sì | V22: OK
A23: 1 | B23: DE LUCA GIOVANNA | C23: NERI MATTEO | D23: IC 12 VITTORIO EMANUELE | E23: 46082 | F23: 46105 | G23: mar | H23: Feriale | I23: 0.375 | J23: 0.45833333 | K23: 0.375 | L23: 0.45833333 | M23: =IF(AND(ISNUMBER(I23),ISNUMBER(J23)),IF(J23>I23,(J23-I23)*24,""),"") -> 2 | N23: =IF(AND(ISNUMBER(K23),ISNUMBER(L23)),IF(L23>K23,(L23-K23)*24,""),"") -> 2 | O23: 2 | P23: =IF(S23="Sì",0,IF(ISNUMBER(O23),O23,IF(ISNUMBER(N23),N23,""))) -> 2 | Q23: =IF(AND(ISNUMBER(O23),ISNUMBER(N23)),O23-N23,"") -> 0 | T23: Sì | V23: OK
A24: 1 | B24: DE LUCA GIOVANNA | C24: NERI MATTEO | D24: IC 12 VITTORIO EMANUELE | E24: 46082 | F24: 46106 | G24: mer | H24: Feriale | I24: 0.375 | J24: 0.45833333 | K24: 0.375 | L24: 0.45833333 | M24: =IF(AND(ISNUMBER(I24),ISNUMBER(J24)),IF(J24>I24,(J24-I24)*24,""),"") -> 2 | N24: =IF(AND(ISNUMBER(K24),ISNUMBER(L24)),IF(L24>K24,(L24-K24)*24,""),"") -> 2 | O24: 2 | P24: =IF(S24="Sì",0,IF(ISNUMBER(O24),O24,IF(ISNUMBER(N24),N24,""))) -> 2 | Q24: =IF(AND(ISNUMBER(O24),ISNUMBER(N24)),O24-N24,"") -> 0 | T24: Sì | V24: OK
A25: 1 | B25: DE LUCA GIOVANNA | C25: NERI MATTEO | D25: IC 12 VITTORIO EMANUELE | E25: 46082 | F25: 46107 | G25: gio | H25: Feriale | I25: 0.375 | J25: 0.45833333 | K25: 0.375 | L25: 0.45833333 | M25: =IF(AND(ISNUMBER(I25),ISNUMBER(J25)),IF(J25>I25,(J25-I25)*24,""),"") -> 2 | N25: =IF(AND(ISNUMBER(K25),ISNUMBER(L25)),IF(L25>K25,(L25-K25)*24,""),"") -> 2 | O25: 2 | P25: =IF(S25="Sì",0,IF(ISNUMBER(O25),O25,IF(ISNUMBER(N25),N25,""))) -> 2 | Q25: =IF(AND(ISNUMBER(O25),ISNUMBER(N25)),O25-N25,"") -> 0 | T25: Sì | V25: OK
A26: 1 | B26: DE LUCA GIOVANNA | C26: NERI MATTEO | D26: IC 12 VITTORIO EMANUELE | E26: 46082 | F26: 46108 | G26: ven | H26: Feriale | I26: 0.375 | J26: 0.45833333 | K26: 0.375 | L26: 0.45833333 | M26: =IF(AND(ISNUMBER(I26),ISNUMBER(J26)),IF(J26>I26,(J26-I26)*24,""),"") -> 2 | N26: =IF(AND(ISNUMBER(K26),ISNUMBER(L26)),IF(L26>K26,(L26-K26)*24,""),"") -> 2 | O26: 2 | P26: =IF(S26="Sì",0,IF(ISNUMBER(O26),O26,IF(ISNUMBER(N26),N26,""))) -> 2 | Q26: =IF(AND(ISNUMBER(O26),ISNUMBER(N26)),O26-N26,"") -> 0 | T26: Sì | V26: OK
A27: 1 | B27: DE LUCA GIOVANNA | C27: NERI MATTEO | D27: IC 12 VITTORIO EMANUELE | E27: 46082 | F27: 46111 | G27: lun | H27: Feriale | I27: 0.375 | J27: 0.45833333 | K27: 0.375 | L27: 0.45833333 | M27: =IF(AND(ISNUMBER(I27),ISNUMBER(J27)),IF(J27>I27,(J27-I27)*24,""),"") -> 2 | N27: =IF(AND(ISNUMBER(K27),ISNUMBER(L27)),IF(L27>K27,(L27-K27)*24,""),"") -> 2 | O27: 2 | P27: =IF(S27="Sì",0,IF(ISNUMBER(O27),O27,IF(ISNUMBER(N27),N27,""))) -> 2 | Q27: =IF(AND(ISNUMBER(O27),ISNUMBER(N27)),O27-N27,"") -> 0 | T27: Sì | V27: OK
A28: 1 | B28: DE LUCA GIOVANNA | C28: NERI MATTEO | D28: IC 12 VITTORIO EMANUELE | E28: 46082 | F28: 46112 | G28: mar | H28: Feriale | I28: 0.375 | J28: 0.45833333 | K28: 0.375 | L28: 0.45833333 | M28: =IF(AND(ISNUMBER(I28),ISNUMBER(J28)),IF(J28>I28,(J28-I28)*24,""),"") -> 2 | N28: =IF(AND(ISNUMBER(K28),ISNUMBER(L28)),IF(L28>K28,(L28-K28)*24,""),"") -> 2 | O28: 2 | P28: =IF(S28="Sì",0,IF(ISNUMBER(O28),O28,IF(ISNUMBER(N28),N28,""))) -> 2 | Q28: =IF(AND(ISNUMBER(O28),ISNUMBER(N28)),O28-N28,"") -> 0 | T28: Sì | V28: OK
A29: 2 | B29: ESPOSITO ANNA | C29: VERDI SOFIA | D29: IC 47 SARRIA-MONTI | E29: 46054 | F29: 46055 | G29: lun | H29: Feriale | I29: 0.45833333 | J29: 0.58333333 | K29: 0.45833333 | L29: 0.58333333 | M29: =IF(AND(ISNUMBER(I29),ISNUMBER(J29)),IF(J29>I29,(J29-I29)*24,""),"") -> 3 | N29: =IF(AND(ISNUMBER(K29),ISNUMBER(L29)),IF(L29>K29,(L29-K29)*24,""),"") -> 3 | O29: 3 | P29: =IF(S29="Sì",0,IF(ISNUMBER(O29),O29,IF(ISNUMBER(N29),N29,""))) -> 3 | Q29: =IF(AND(ISNUMBER(O29),ISNUMBER(N29)),O29-N29,"") -> 0 | T29: Sì | V29: OK
A30: 2 | B30: ESPOSITO ANNA | C30: VERDI SOFIA | D30: IC 47 SARRIA-MONTI | E30: 46054 | F30: 46056 | G30: mar | H30: Feriale | I30: 0.45833333 | J30: 0.58333333 | K30: 0.45833333 | L30: 0.58333333 | M30: =IF(AND(ISNUMBER(I30),ISNUMBER(J30)),IF(J30>I30,(J30-I30)*24,""),"") -> 3 | N30: =IF(AND(ISNUMBER(K30),ISNUMBER(L30)),IF(L30>K30,(L30-K30)*24,""),"") -> 3 | O30: 3 | P30: =IF(S30="Sì",0,IF(ISNUMBER(O30),O30,IF(ISNUMBER(N30),N30,""))) -> 3 | Q30: =IF(AND(ISNUMBER(O30),ISNUMBER(N30)),O30-N30,"") -> 0 | T30: Sì | V30: OK
A31: 2 | B31: ESPOSITO ANNA | C31: VERDI SOFIA | D31: IC 47 SARRIA-MONTI | E31: 46054 | F31: 46058 | G31: gio | H31: Feriale | I31: 0.45833333 | J31: 0.58333333 | K31: 0.45833333 | L31: 0.58333333 | M31: =IF(AND(ISNUMBER(I31),ISNUMBER(J31)),IF(J31>I31,(J31-I31)*24,""),"") -> 3 | N31: =IF(AND(ISNUMBER(K31),ISNUMBER(L31)),IF(L31>K31,(L31-K31)*24,""),"") -> 3 | O31: 3 | P31: =IF(S31="Sì",0,IF(ISNUMBER(O31),O31,IF(ISNUMBER(N31),N31,""))) -> 3 | Q31: =IF(AND(ISNUMBER(O31),ISNUMBER(N31)),O31-N31,"") -> 0 | T31: Sì | V31: OK
A32: 2 | B32: ESPOSITO ANNA | C32: VERDI SOFIA | D32: IC 47 SARRIA-MONTI | E32: 46054 | F32: 46059 | G32: ven | H32: Feriale | I32: 0.45833333 | J32: 0.58333333 | K32: 0.45833333 | L32: 0.58333333 | M32: =IF(AND(ISNUMBER(I32),ISNUMBER(J32)),IF(J32>I32,(J32-I32)*24,""),"") -> 3 | N32: =IF(AND(ISNUMBER(K32),ISNUMBER(L32)),IF(L32>K32,(L32-K32)*24,""),"") -> 3 | O32: 3 | P32: =IF(S32="Sì",0,IF(ISNUMBER(O32),O32,IF(ISNUMBER(N32),N32,""))) -> 3 | Q32: =IF(AND(ISNUMBER(O32),ISNUMBER(N32)),O32-N32,"") -> 0 | T32: Sì | V32: OK
A33: 2 | B33: ESPOSITO ANNA | C33: VERDI SOFIA | D33: IC 47 SARRIA-MONTI | E33: 46054 | F33: 46062 | G33: lun | H33: Feriale | I33: 0.45833333 | J33: 0.58333333 | K33: 0.45833333 | L33: 0.58333333 | M33: =IF(AND(ISNUMBER(I33),ISNUMBER(J33)),IF(J33>I33,(J33-I33)*24,""),"") -> 3 | N33: =IF(AND(ISNUMBER(K33),ISNUMBER(L33)),IF(L33>K33,(L33-K33)*24,""),"") -> 3 | O33: 3 | P33: =IF(S33="Sì",0,IF(ISNUMBER(O33),O33,IF(ISNUMBER(N33),N33,""))) -> 3 | Q33: =IF(AND(ISNUMBER(O33),ISNUMBER(N33)),O33-N33,"") -> 0 | T33: Sì | V33: OK
A34: 2 | B34: ESPOSITO ANNA | C34: VERDI SOFIA | D34: IC 47 SARRIA-MONTI | E34: 46054 | F34: 46063 | G34: mar | H34: Feriale | I34: 0.45833333 | J34: 0.58333333 | M34: =IF(AND(ISNUMBER(I34),ISNUMBER(J34)),IF(J34>I34,(J34-I34)*24,""),"") -> 3 | N34: =IF(AND(ISNUMBER(K34),ISNUMBER(L34)),IF(L34>K34,(L34-K34)*24,""),"") | P34: =IF(S34="Sì",0,IF(ISNUMBER(O34),O34,IF(ISNUMBER(N34),N34,""))) -> 0 | Q34: =IF(AND(ISNUMBER(O34),ISNUMBER(N34)),O34-N34,"") | S34: Sì | U34: 104 | V34: Assenza operatore | W34: Assenza dell'operatore – nota «104» (permesso Legge 104/1992); 3 ore programmate non svolte.
A35: 2 | B35: ESPOSITO ANNA | C35: VERDI SOFIA | D35: IC 47 SARRIA-MONTI | E35: 46054 | F35: 46065 | G35: gio | H35: Feriale | I35: 0.45833333 | J35: 0.58333333 | K35: 0.45833333 | L35: 0.58333333 | M35: =IF(AND(ISNUMBER(I35),ISNUMBER(J35)),IF(J35>I35,(J35-I35)*24,""),"") -> 3 | N35: =IF(AND(ISNUMBER(K35),ISNUMBER(L35)),IF(L35>K35,(L35-K35)*24,""),"") -> 3 | O35: 3 | P35: =IF(S35="Sì",0,IF(ISNUMBER(O35),O35,IF(ISNUMBER(N35),N35,""))) -> 3 | Q35: =IF(AND(ISNUMBER(O35),ISNUMBER(N35)),O35-N35,"") -> 0 | T35: Sì | V35: OK
A36: 2 | B36: ESPOSITO ANNA | C36: VERDI SOFIA | D36: IC 47 SARRIA-MONTI | E36: 46054 | F36: 46066 | G36: ven | H36: Feriale | I36: 0.45833333 | J36: 0.58333333 | K36: 0.45833333 | L36: 0.58333333 | M36: =IF(AND(ISNUMBER(I36),ISNUMBER(J36)),IF(J36>I36,(J36-I36)*24,""),"") -> 3 | N36: =IF(AND(ISNUMBER(K36),ISNUMBER(L36)),IF(L36>K36,(L36-K36)*24,""),"") -> 3 | O36: 3 | P36: =IF(S36="Sì",0,IF(ISNUMBER(O36),O36,IF(ISNUMBER(N36),N36,""))) -> 3 | Q36: =IF(AND(ISNUMBER(O36),ISNUMBER(N36)),O36-N36,"") -> 0 | T36: Sì | V36: OK
A37: 2 | B37: ESPOSITO ANNA | C37: VERDI SOFIA | D37: IC 47 SARRIA-MONTI | E37: 46054 | F37: 46069 | G37: lun | H37: Feriale | I37: 0.45833333 | J37: 0.58333333 | K37: 0.45833333 | L37: 0.58333333 | M37: =IF(AND(ISNUMBER(I37),ISNUMBER(J37)),IF(J37>I37,(J37-I37)*24,""),"") -> 3 | N37: =IF(AND(ISNUMBER(K37),ISNUMBER(L37)),IF(L37>K37,(L37-K37)*24,""),"") -> 3 | O37: 3 | P37: =IF(S37="Sì",0,IF(ISNUMBER(O37),O37,IF(ISNUMBER(N37),N37,""))) -> 3 | Q37: =IF(AND(ISNUMBER(O37),ISNUMBER(N37)),O37-N37,"") -> 0 | T37: Sì | V37: OK
A38: 2 | B38: ESPOSITO ANNA | C38: VERDI SOFIA | D38: IC 47 SARRIA-MONTI | E38: 46054 | F38: 46070 | G38: mar | H38: Feriale | I38: 0.45833333 | J38: 0.58333333 | K38: 0.45833333 | L38: 0.58333333 | M38: =IF(AND(ISNUMBER(I38),ISNUMBER(J38)),IF(J38>I38,(J38-I38)*24,""),"") -> 3 | N38: =IF(AND(ISNUMBER(K38),ISNUMBER(L38)),IF(L38>K38,(L38-K38)*24,""),"") -> 3 | O38: 3 | P38: =IF(S38="Sì",0,IF(ISNUMBER(O38),O38,IF(ISNUMBER(N38),N38,""))) -> 3 | Q38: =IF(AND(ISNUMBER(O38),ISNUMBER(N38)),O38-N38,"") -> 0 | T38: Sì | V38: OK
A39: 2 | B39: ESPOSITO ANNA | C39: VERDI SOFIA | D39: IC 47 SARRIA-MONTI | E39: 46054 | F39: 46072 | G39: gio | H39: Feriale | I39: 0.45833333 | J39: 0.58333333 | K39: 0.45833333 | L39: 0.58333333 | M39: =IF(AND(ISNUMBER(I39),ISNUMBER(J39)),IF(J39>I39,(J39-I39)*24,""),"") -> 3 | N39: =IF(AND(ISNUMBER(K39),ISNUMBER(L39)),IF(L39>K39,(L39-K39)*24,""),"") -> 3 | O39: 3 | P39: =IF(S39="Sì",0,IF(ISNUMBER(O39),O39,IF(ISNUMBER(N39),N39,""))) -> 3 | Q39: =IF(AND(ISNUMBER(O39),ISNUMBER(N39)),O39-N39,"") -> 0 | T39: Sì | V39: OK
A40: 2 | B40: ESPOSITO ANNA | C40: VERDI SOFIA | D40: IC 47 SARRIA-MONTI | E40: 46054 | F40: 46073 | G40: ven | H40: Feriale | I40: 0.45833333 | J40: 0.58333333 | K40: 0.45833333 | L40: 0.58333333 | M40: =IF(AND(ISNUMBER(I40),ISNUMBER(J40)),IF(J40>I40,(J40-I40)*24,""),"") -> 3 | N40: =IF(AND(ISNUMBER(K40),ISNUMBER(L40)),IF(L40>K40,(L40-K40)*24,""),"") -> 3 | O40: 3 | P40: =IF(S40="Sì",0,IF(ISNUMBER(O40),O40,IF(ISNUMBER(N40),N40,""))) -> 3 | Q40: =IF(AND(ISNUMBER(O40),ISNUMBER(N40)),O40-N40,"") -> 0 | T40: Sì | V40: OK
A41: 2 | B41: ESPOSITO ANNA | C41: VERDI SOFIA | D41: IC 47 SARRIA-MONTI | E41: 46054 | F41: 46076 | G41: lun | H41: Feriale | I41: 0.45833333 | J41: 0.58333333 | K41: 0.45833333 | L41: 0.58333333 | M41: =IF(AND(ISNUMBER(I41),ISNUMBER(J41)),IF(J41>I41,(J41-I41)*24,""),"") -> 3 | N41: =IF(AND(ISNUMBER(K41),ISNUMBER(L41)),IF(L41>K41,(L41-K41)*24,""),"") -> 3 | O41: 3 | P41: =IF(S41="Sì",0,IF(ISNUMBER(O41),O41,IF(ISNUMBER(N41),N41,""))) -> 3 | Q41: =IF(AND(ISNUMBER(O41),ISNUMBER(N41)),O41-N41,"") -> 0 | T41: Sì | V41: OK
...

Sheet DE LUCA G. 03-2026
A1: COMUNE DI NAPOLI · Assistenza Specialistica | Q1: Foglio 1 di 4
A2: Foglio firma mensile · Assistenza Specialistica all'integrazione scolastica destinato agli alunni disabili · Anno scolastico 2025/2026
Q4: ‹ Torna al Riepilogo
A5: Ente | D5: COOPERATIVA SOCIALE SIRIO | I5: Mese/anno di riferimento | L5: 46082 | O5: STATO DEL DOCUMENTO
A6: Istituto scolastico | D6: IC 12 VITTORIO EMANUELE | I6: Ore da PEI (settimanali) | L6: 10 | O6: DA VERIFICARE
A7: Operatore | D7: DE LUCA GIOVANNA | I7: Sostituzione | L7: Sì
A8: Alunno | D8: NERI MATTEO | I8: Data di compilazione | L8: 46112 | O8: 0 errori · 4 attenzioni · 3 informazioni
A9: Lotto | D9: 1 | I9: Firma coordinatore ente | L9: Presente | O9: 0 campi illeggibili · 1 lettura incerta · 0 correzioni manuali
A10: Municipalità | D10: 2 | I10: Timbro referente scolastico | L10: Assente | O10: Non ancora confermato in revisione
M11: Calcoli e controlli di Sirio OCR
A12: Giorno | B12: Data | C12: Gg. | D12: Orario programmato | F12: Orario effettivo | H12: Tot. ore effettive | I12: Assenza alunno | J12: Assenza operatore | K12: Firma operatore | L12: Note | M12: Ore programmate | N12: Ore calcolate | O12: Ore riconosciute | P12: Differenza dich. − calc. | Q12: Esito dei controlli
D13: Entrata | E13: Uscita | F13: Entrata | G13: Uscita
A14: 1 | B14: 46082 | C14: dom | M14: =IF(AND(ISNUMBER(D14),ISNUMBER(E14)),IF(E14>D14,(E14-D14)*24,""),"") | N14: =IF(AND(ISNUMBER(F14),ISNUMBER(G14)),IF(G14>F14,(G14-F14)*24,""),"") | O14: =IF(J14="X",0,IF(ISNUMBER(H14),H14,IF(ISNUMBER(N14),N14,""))) | P14: =IF(AND(ISNUMBER(H14),ISNUMBER(N14)),H14-N14,"") | Q14: Domenica
A15: 2 | B15: 46083 | C15: lun | D15: 0.375 | E15: 0.45833333 | F15: 0.375 | G15: 0.45833333 | H15: 2 | K15: Sì | M15: =IF(AND(ISNUMBER(D15),ISNUMBER(E15)),IF(E15>D15,(E15-D15)*24,""),"") -> 2 | N15: =IF(AND(ISNUMBER(F15),ISNUMBER(G15)),IF(G15>F15,(G15-F15)*24,""),"") -> 2 | O15: =IF(J15="X",0,IF(ISNUMBER(H15),H15,IF(ISNUMBER(N15),N15,""))) -> 2 | P15: =IF(AND(ISNUMBER(H15),ISNUMBER(N15)),H15-N15,"") -> 0 | Q15: OK
A16: 3 | B16: 46084 | C16: mar | D16: 0.375 | E16: 0.45833333 | F16: 0.375 | G16: 0.45833333 | H16: 2 | K16: Sì | M16: =IF(AND(ISNUMBER(D16),ISNUMBER(E16)),IF(E16>D16,(E16-D16)*24,""),"") -> 2 | N16: =IF(AND(ISNUMBER(F16),ISNUMBER(G16)),IF(G16>F16,(G16-F16)*24,""),"") -> 2 | O16: =IF(J16="X",0,IF(ISNUMBER(H16),H16,IF(ISNUMBER(N16),N16,""))) -> 2 | P16: =IF(AND(ISNUMBER(H16),ISNUMBER(N16)),H16-N16,"") -> 0 | Q16: OK
A17: 4 | B17: 46085 | C17: mer | D17: 0.375 | E17: 0.45833333 | F17: 0.375 | G17: 0.45833333 | H17: 2 | K17: Sì | M17: =IF(AND(ISNUMBER(D17),ISNUMBER(E17)),IF(E17>D17,(E17-D17)*24,""),"") -> 2 | N17: =IF(AND(ISNUMBER(F17),ISNUMBER(G17)),IF(G17>F17,(G17-F17)*24,""),"") -> 2 | O17: =IF(J17="X",0,IF(ISNUMBER(H17),H17,IF(ISNUMBER(N17),N17,""))) -> 2 | P17: =IF(AND(ISNUMBER(H17),ISNUMBER(N17)),H17-N17,"") -> 0 | Q17: OK
A18: 5 | B18: 46086 | C18: gio | D18: 0.375 | E18: 0.45833333 | F18: 0.375 | G18: 0.45833333 | H18: 2 | K18: Sì | M18: =IF(AND(ISNUMBER(D18),ISNUMBER(E18)),IF(E18>D18,(E18-D18)*24,""),"") -> 2 | N18: =IF(AND(ISNUMBER(F18),ISNUMBER(G18)),IF(G18>F18,(G18-F18)*24,""),"") -> 2 | O18: =IF(J18="X",0,IF(ISNUMBER(H18),H18,IF(ISNUMBER(N18),N18,""))) -> 2 | P18: =IF(AND(ISNUMBER(H18),ISNUMBER(N18)),H18-N18,"") -> 0 | Q18: OK
A19: 6 | B19: 46087 | C19: ven | D19: 0.375 | E19: 0.45833333 | F19: 0.375 | G19: 0.45833333 | H19: 2 | K19: Sì | M19: =IF(AND(ISNUMBER(D19),ISNUMBER(E19)),IF(E19>D19,(E19-D19)*24,""),"") -> 2 | N19: =IF(AND(ISNUMBER(F19),ISNUMBER(G19)),IF(G19>F19,(G19-F19)*24,""),"") -> 2 | O19: =IF(J19="X",0,IF(ISNUMBER(H19),H19,IF(ISNUMBER(N19),N19,""))) -> 2 | P19: =IF(AND(ISNUMBER(H19),ISNUMBER(N19)),H19-N19,"") -> 0 | Q19: OK
A20: 7 | B20: 46088 | C20: sab | M20: =IF(AND(ISNUMBER(D20),ISNUMBER(E20)),IF(E20>D20,(E20-D20)*24,""),"") | N20: =IF(AND(ISNUMBER(F20),ISNUMBER(G20)),IF(G20>F20,(G20-F20)*24,""),"") | O20: =IF(J20="X",0,IF(ISNUMBER(H20),H20,IF(ISNUMBER(N20),N20,""))) | P20: =IF(AND(ISNUMBER(H20),ISNUMBER(N20)),H20-N20,"") | Q20: Sabato
A21: 8 | B21: 46089 | C21: dom | M21: =IF(AND(ISNUMBER(D21),ISNUMBER(E21)),IF(E21>D21,(E21-D21)*24,""),"") | N21: =IF(AND(ISNUMBER(F21),ISNUMBER(G21)),IF(G21>F21,(G21-F21)*24,""),"") | O21: =IF(J21="X",0,IF(ISNUMBER(H21),H21,IF(ISNUMBER(N21),N21,""))) | P21: =IF(AND(ISNUMBER(H21),ISNUMBER(N21)),H21-N21,"") | Q21: Domenica
A22: 9 | B22: 46090 | C22: lun | D22: 0.375 | E22: 0.45833333 | F22: 0.375 | G22: 0.45833333 | H22: 2 | K22: Sì | M22: =IF(AND(ISNUMBER(D22),ISNUMBER(E22)),IF(E22>D22,(E22-D22)*24,""),"") -> 2 | N22: =IF(AND(ISNUMBER(F22),ISNUMBER(G22)),IF(G22>F22,(G22-F22)*24,""),"") -> 2 | O22: =IF(J22="X",0,IF(ISNUMBER(H22),H22,IF(ISNUMBER(N22),N22,""))) -> 2 | P22: =IF(AND(ISNUMBER(H22),ISNUMBER(N22)),H22-N22,"") -> 0 | Q22: OK
A23: 10 | B23: 46091 | C23: mar | D23: 0.375 | E23: 0.45833333 | F23: 0.375 | G23: 0.45833333 | H23: 2 | K23: Sì | M23: =IF(AND(ISNUMBER(D23),ISNUMBER(E23)),IF(E23>D23,(E23-D23)*24,""),"") -> 2 | N23: =IF(AND(ISNUMBER(F23),ISNUMBER(G23)),IF(G23>F23,(G23-F23)*24,""),"") -> 2 | O23: =IF(J23="X",0,IF(ISNUMBER(H23),H23,IF(ISNUMBER(N23),N23,""))) -> 2 | P23: =IF(AND(ISNUMBER(H23),ISNUMBER(N23)),H23-N23,"") -> 0 | Q23: OK
A24: 11 | B24: 46092 | C24: mer | D24: 0.375 | E24: 0.45833333 | F24: 0.375 | G24: 0.45833333 | H24: 2 | K24: Sì | M24: =IF(AND(ISNUMBER(D24),ISNUMBER(E24)),IF(E24>D24,(E24-D24)*24,""),"") -> 2 | N24: =IF(AND(ISNUMBER(F24),ISNUMBER(G24)),IF(G24>F24,(G24-F24)*24,""),"") -> 2 | O24: =IF(J24="X",0,IF(ISNUMBER(H24),H24,IF(ISNUMBER(N24),N24,""))) -> 2 | P24: =IF(AND(ISNUMBER(H24),ISNUMBER(N24)),H24-N24,"") -> 0 | Q24: OK
A25: 12 | B25: 46093 | C25: gio | D25: 0.375 | E25: 0.45833333 | F25: 0.375 | G25: 0.45833333 | H25: 2 | K25: Sì | M25: =IF(AND(ISNUMBER(D25),ISNUMBER(E25)),IF(E25>D25,(E25-D25)*24,""),"") -> 2 | N25: =IF(AND(ISNUMBER(F25),ISNUMBER(G25)),IF(G25>F25,(G25-F25)*24,""),"") -> 2 | O25: =IF(J25="X",0,IF(ISNUMBER(H25),H25,IF(ISNUMBER(N25),N25,""))) -> 2 | P25: =IF(AND(ISNUMBER(H25),ISNUMBER(N25)),H25-N25,"") -> 0 | Q25: OK
A26: 13 | B26: 46094 | C26: ven | D26: 0.375 | E26: 0.45833333 | F26: 0.375 | G26: 0.45833333 | H26: 2 | K26: Sì | M26: =IF(AND(ISNUMBER(D26),ISNUMBER(E26)),IF(E26>D26,(E26-D26)*24,""),"") -> 2 | N26: =IF(AND(ISNUMBER(F26),ISNUMBER(G26)),IF(G26>F26,(G26-F26)*24,""),"") -> 2 | O26: =IF(J26="X",0,IF(ISNUMBER(H26),H26,IF(ISNUMBER(N26),N26,""))) -> 2 | P26: =IF(AND(ISNUMBER(H26),ISNUMBER(N26)),H26-N26,"") -> 0 | Q26: OK
A27: 14 | B27: 46095 | C27: sab | F27: 0.375 | G27: 0.45833333 | H27: 2 | K27: Sì | L27: RECUPERO | M27: =IF(AND(ISNUMBER(D27),ISNUMBER(E27)),IF(E27>D27,(E27-D27)*24,""),"") | N27: =IF(AND(ISNUMBER(F27),ISNUMBER(G27)),IF(G27>F27,(G27-F27)*24,""),"") -> 2 | O27: =IF(J27="X",0,IF(ISNUMBER(H27),H27,IF(ISNUMBER(N27),N27,""))) -> 2 | P27: =IF(AND(ISNUMBER(H27),ISNUMBER(N27)),H27-N27,"") -> 0 | Q27: OK
A28: 15 | B28: 46096 | C28: dom | M28: =IF(AND(ISNUMBER(D28),ISNUMBER(E28)),IF(E28>D28,(E28-D28)*24,""),"") | N28: =IF(AND(ISNUMBER(F28),ISNUMBER(G28)),IF(G28>F28,(G28-F28)*24,""),"") | O28: =IF(J28="X",0,IF(ISNUMBER(H28),H28,IF(ISNUMBER(N28),N28,""))) | P28: =IF(AND(ISNUMBER(H28),ISNUMBER(N28)),H28-N28,"") | Q28: Domenica
A29: 16 | B29: 46097 | C29: lun | D29: 0.375 | E29: 0.45833333 | F29: 0.375 | G29: 0.45833333 | H29: 2 | K29: Sì | M29: =IF(AND(ISNUMBER(D29),ISNUMBER(E29)),IF(E29>D29,(E29-D29)*24,""),"") -> 2 | N29: =IF(AND(ISNUMBER(F29),ISNUMBER(G29)),IF(G29>F29,(G29-F29)*24,""),"") -> 2 | O29: =IF(J29="X",0,IF(ISNUMBER(H29),H29,IF(ISNUMBER(N29),N29,""))) -> 2 | P29: =IF(AND(ISNUMBER(H29),ISNUMBER(N29)),H29-N29,"") -> 0 | Q29: OK
A30: 17 | B30: 46098 | C30: mar | D30: 0.375 | E30: 0.45833333 | F30: 0.375 | G30: 0.45833333 | H30: 2 | K30: Sì | M30: =IF(AND(ISNUMBER(D30),ISNUMBER(E30)),IF(E30>D30,(E30-D30)*24,""),"") -> 2 | N30: =IF(AND(ISNUMBER(F30),ISNUMBER(G30)),IF(G30>F30,(G30-F30)*24,""),"") -> 2 | O30: =IF(J30="X",0,IF(ISNUMBER(H30),H30,IF(ISNUMBER(N30),N30,""))) -> 2 | P30: =IF(AND(ISNUMBER(H30),ISNUMBER(N30)),H30-N30,"") -> 0 | Q30: OK
A31: 18 | B31: 46099 | C31: mer | D31: 0.375 | E31: 0.45833333 | F31: 0.375 | G31: 0.45833333 | H31: 2 | K31: Sì | M31: =IF(AND(ISNUMBER(D31),ISNUMBER(E31)),IF(E31>D31,(E31-D31)*24,""),"") -> 2 | N31: =IF(AND(ISNUMBER(F31),ISNUMBER(G31)),IF(G31>F31,(G31-F31)*24,""),"") -> 2 | O31: =IF(J31="X",0,IF(ISNUMBER(H31),H31,IF(ISNUMBER(N31),N31,""))) -> 2 | P31: =IF(AND(ISNUMBER(H31),ISNUMBER(N31)),H31-N31,"") -> 0 | Q31: OK
A32: 19 | B32: 46100 | C32: gio | D32: 0.375 | E32: 0.45833333 | F32: 0.375 | G32: 0.45833333 | H32: 2 | K32: Sì | M32: =IF(AND(ISNUMBER(D32),ISNUMBER(E32)),IF(E32>D32,(E32-D32)*24,""),"") -> 2 | N32: =IF(AND(ISNUMBER(F32),ISNUMBER(G32)),IF(G32>F32,(G32-F32)*24,""),"") -> 2 | O32: =IF(J32="X",0,IF(ISNUMBER(H32),H32,IF(ISNUMBER(N32),N32,""))) -> 2 | P32: =IF(AND(ISNUMBER(H32),ISNUMBER(N32)),H32-N32,"") -> 0 | Q32: OK
A33: 20 | B33: 46101 | C33: ven | D33: 0.375 | E33: 0.45833333 | F33: 0.375 | G33: 0.46875 | H33: 2.25 | K33: Sì | M33: =IF(AND(ISNUMBER(D33),ISNUMBER(E33)),IF(E33>D33,(E33-D33)*24,""),"") -> 2 | N33: =IF(AND(ISNUMBER(F33),ISNUMBER(G33)),IF(G33>F33,(G33-F33)*24,""),"") -> 2.25 | O33: =IF(J33="X",0,IF(ISNUMBER(H33),H33,IF(ISNUMBER(N33),N33,""))) -> 2.25 | P33: =IF(AND(ISNUMBER(H33),ISNUMBER(N33)),H33-N33,"") -> 0 | Q33: OK
A34: 21 | B34: 46102 | C34: sab | M34: =IF(AND(ISNUMBER(D34),ISNUMBER(E34)),IF(E34>D34,(E34-D34)*24,""),"") | N34: =IF(AND(ISNUMBER(F34),ISNUMBER(G34)),IF(G34>F34,(G34-F34)*24,""),"") | O34: =IF(J34="X",0,IF(ISNUMBER(H34),H34,IF(ISNUMBER(N34),N34,""))) | P34: =IF(AND(ISNUMBER(H34),ISNUMBER(N34)),H34-N34,"") | Q34: Sabato
A35: 22 | B35: 46103 | C35: dom | M35: =IF(AND(ISNUMBER(D35),ISNUMBER(E35)),IF(E35>D35,(E35-D35)*24,""),"") | N35: =IF(AND(ISNUMBER(F35),ISNUMBER(G35)),IF(G35>F35,(G35-F35)*24,""),"") | O35: =IF(J35="X",0,IF(ISNUMBER(H35),H35,IF(ISNUMBER(N35),N35,""))) | P35: =IF(AND(ISNUMBER(H35),ISNUMBER(N35)),H35-N35,"") | Q35: Domenica
A36: 23 | B36: 46104 | C36: lun | D36: 0.375 | E36: 0.45833333 | F36: 0.375 | G36: 0.45833333 | H36: 2 | K36: Sì | M36: =IF(AND(ISNUMBER(D36),ISNUMBER(E36)),IF(E36>D36,(E36-D36)*24,""),"") -> 2 | N36: =IF(AND(ISNUMBER(F36),ISNUMBER(G36)),IF(G36>F36,(G36-F36)*24,""),"") -> 2 | O36: =IF(J36="X",0,IF(ISNUMBER(H36),H36,IF(ISNUMBER(N36),N36,""))) -> 2 | P36: =IF(AND(ISNUMBER(H36),ISNUMBER(N36)),H36-N36,"") -> 0 | Q36: OK
A37: 24 | B37: 46105 | C37: mar | D37: 0.375 | E37: 0.45833333 | F37: 0.375 | G37: 0.45833333 | H37: 2 | K37: Sì | M37: =IF(AND(ISNUMBER(D37),ISNUMBER(E37)),IF(E37>D37,(E37-D37)*24,""),"") -> 2 | N37: =IF(AND(ISNUMBER(F37),ISNUMBER(G37)),IF(G37>F37,(G37-F37)*24,""),"") -> 2 | O37: =IF(J37="X",0,IF(ISNUMBER(H37),H37,IF(ISNUMBER(N37),N37,""))) -> 2 | P37: =IF(AND(ISNUMBER(H37),ISNUMBER(N37)),H37-N37,"") -> 0 | Q37: OK
A38: 25 | B38: 46106 | C38: mer | D38: 0.375 | E38: 0.45833333 | F38: 0.375 | G38: 0.45833333 | H38: 2 | K38: Sì | M38: =IF(AND(ISNUMBER(D38),ISNUMBER(E38)),IF(E38>D38,(E38-D38)*24,""),"") -> 2 | N38: =IF(AND(ISNUMBER(F38),ISNUMBER(G38)),IF(G38>F38,(G38-F38)*24,""),"") -> 2 | O38: =IF(J38="X",0,IF(ISNUMBER(H38),H38,IF(ISNUMBER(N38),N38,""))) -> 2 | P38: =IF(AND(ISNUMBER(H38),ISNUMBER(N38)),H38-N38,"") -> 0 | Q38: OK
A39: 26 | B39: 46107 | C39: gio | D39: 0.375 | E39: 0.45833333 | F39: 0.375 | G39: 0.45833333 | H39: 2 | K39: Sì | M39: =IF(AND(ISNUMBER(D39),ISNUMBER(E39)),IF(E39>D39,(E39-D39)*24,""),"") -> 2 | N39: =IF(AND(ISNUMBER(F39),ISNUMBER(G39)),IF(G39>F39,(G39-F39)*24,""),"") -> 2 | O39: =IF(J39="X",0,IF(ISNUMBER(H39),H39,IF(ISNUMBER(N39),N39,""))) -> 2 | P39: =IF(AND(ISNUMBER(H39),ISNUMBER(N39)),H39-N39,"") -> 0 | Q39: OK
A40: 27 | B40: 46108 | C40: ven | D40: 0.375 | E40: 0.45833333 | F40: 0.375 | G40: 0.45833333 | H40: 2 | K40: Sì | M40: =IF(AND(ISNUMBER(D40),ISNUMBER(E40)),IF(E40>D40,(E40-D40)*24,""),"") -> 2 | N40: =IF(AND(ISNUMBER(F40),ISNUMBER(G40)),IF(G40>F40,(G40-F40)*24,""),"") -> 2 | O40: =IF(J40="X",0,IF(ISNUMBER(H40),H40,IF(ISNUMBER(N40),N40,""))) -> 2 | P40: =IF(AND(ISNUMBER(H40),ISNUMBER(N40)),H40-N40,"") -> 0 | Q40: OK
A41: 28 | B41: 46109 | C41: sab | M41: =IF(AND(ISNUMBER(D41),ISNUMBER(E41)),IF(E41>D41,(E41-D41)*24,""),"") | N41: =IF(AND(ISNUMBER(F41),ISNUMBER(G41)),IF(G41>F41,(G41-F41)*24,""),"") | O41: =IF(J41="X",0,IF(ISNUMBER(H41),H41,IF(ISNUMBER(N41),N41,""))) | P41: =IF(AND(ISNUMBER(H41),ISNUMBER(N41)),H41-N41,"") | Q41: Sabato
...

Sheet ESPOSITO A. 02-2026
A1: COMUNE DI NAPOLI · Assistenza Specialistica | Q1: Foglio 2 di 4
A2: Foglio firma mensile · Assistenza Specialistica all'integrazione scolastica destinato agli alunni disabili · Anno scolastico 2025/2026
Q4: ‹ Torna al Riepilogo
A5: Ente | D5: COOPERATIVA SOCIALE SIRIO | I5: Mese/anno di riferimento | L5: 46054 | O5: STATO DEL DOCUMENTO
A6: Istituto scolastico | D6: IC 47 SARRIA-MONTI | I6: Ore da PEI (settimanali) | L6: 12 | O6: OK
A7: Operatore | D7: ESPOSITO ANNA | I7: Sostituzione | L7: No
A8: Alunno | D8: VERDI SOFIA | I8: Data di compilazione | L8: 46080 | O8: 0 errori · 0 attenzioni · 1 informazione
A9: Lotto | D9: 1 | I9: Firma coordinatore ente | L9: Presente | O9: 0 campi illeggibili · 0 letture incerte · 1 correzione manuale
A10: Municipalità | D10: 2 | I10: Timbro referente scolastico | L10: Presente | O10: Confermato in revisione
M11: Calcoli e controlli di Sirio OCR
A12: Giorno | B12: Data | C12: Gg. | D12: Orario programmato | F12: Orario effettivo | H12: Tot. ore effettive | I12: Assenza alunno | J12: Assenza operatore | K12: Firma operatore | L12: Note | M12: Ore programmate | N12: Ore calcolate | O12: Ore riconosciute | P12: Differenza dich. − calc. | Q12: Esito dei controlli
D13: Entrata | E13: Uscita | F13: Entrata | G13: Uscita
A14: 1 | B14: 46054 | C14: dom | M14: =IF(AND(ISNUMBER(D14),ISNUMBER(E14)),IF(E14>D14,(E14-D14)*24,""),"") | N14: =IF(AND(ISNUMBER(F14),ISNUMBER(G14)),IF(G14>F14,(G14-F14)*24,""),"") | O14: =IF(J14="X",0,IF(ISNUMBER(H14),H14,IF(ISNUMBER(N14),N14,""))) | P14: =IF(AND(ISNUMBER(H14),ISNUMBER(N14)),H14-N14,"") | Q14: Domenica
A15: 2 | B15: 46055 | C15: lun | D15: 0.45833333 | E15: 0.58333333 | F15: 0.45833333 | G15: 0.58333333 | H15: 3 | K15: Sì | M15: =IF(AND(ISNUMBER(D15),ISNUMBER(E15)),IF(E15>D15,(E15-D15)*24,""),"") -> 3 | N15: =IF(AND(ISNUMBER(F15),ISNUMBER(G15)),IF(G15>F15,(G15-F15)*24,""),"") -> 3 | O15: =IF(J15="X",0,IF(ISNUMBER(H15),H15,IF(ISNUMBER(N15),N15,""))) -> 3 | P15: =IF(AND(ISNUMBER(H15),ISNUMBER(N15)),H15-N15,"") -> 0 | Q15: OK
A16: 3 | B16: 46056 | C16: mar | D16: 0.45833333 | E16: 0.58333333 | F16: 0.45833333 | G16: 0.58333333 | H16: 3 | K16: Sì | M16: =IF(AND(ISNUMBER(D16),ISNUMBER(E16)),IF(E16>D16,(E16-D16)*24,""),"") -> 3 | N16: =IF(AND(ISNUMBER(F16),ISNUMBER(G16)),IF(G16>F16,(G16-F16)*24,""),"") -> 3 | O16: =IF(J16="X",0,IF(ISNUMBER(H16),H16,IF(ISNUMBER(N16),N16,""))) -> 3 | P16: =IF(AND(ISNUMBER(H16),ISNUMBER(N16)),H16-N16,"") -> 0 | Q16: OK
A17: 4 | B17: 46057 | C17: mer | M17: =IF(AND(ISNUMBER(D17),ISNUMBER(E17)),IF(E17>D17,(E17-D17)*24,""),"") | N17: =IF(AND(ISNUMBER(F17),ISNUMBER(G17)),IF(G17>F17,(G17-F17)*24,""),"") | O17: =IF(J17="X",0,IF(ISNUMBER(H17),H17,IF(ISNUMBER(N17),N17,""))) | P17: =IF(AND(ISNUMBER(H17),ISNUMBER(N17)),H17-N17,"")
A18: 5 | B18: 46058 | C18: gio | D18: 0.45833333 | E18: 0.58333333 | F18: 0.45833333 | G18: 0.58333333 | H18: 3 | K18: Sì | M18: =IF(AND(ISNUMBER(D18),ISNUMBER(E18)),IF(E18>D18,(E18-D18)*24,""),"") -> 3 | N18: =IF(AND(ISNUMBER(F18),ISNUMBER(G18)),IF(G18>F18,(G18-F18)*24,""),"") -> 3 | O18: =IF(J18="X",0,IF(ISNUMBER(H18),H18,IF(ISNUMBER(N18),N18,""))) -> 3 | P18: =IF(AND(ISNUMBER(H18),ISNUMBER(N18)),H18-N18,"") -> 0 | Q18: OK
A19: 6 | B19: 46059 | C19: ven | D19: 0.45833333 | E19: 0.58333333 | F19: 0.45833333 | G19: 0.58333333 | H19: 3 | K19: Sì | M19: =IF(AND(ISNUMBER(D19),ISNUMBER(E19)),IF(E19>D19,(E19-D19)*24,""),"") -> 3 | N19: =IF(AND(ISNUMBER(F19),ISNUMBER(G19)),IF(G19>F19,(G19-F19)*24,""),"") -> 3 | O19: =IF(J19="X",0,IF(ISNUMBER(H19),H19,IF(ISNUMBER(N19),N19,""))) -> 3 | P19: =IF(AND(ISNUMBER(H19),ISNUMBER(N19)),H19-N19,"") -> 0 | Q19: OK
A20: 7 | B20: 46060 | C20: sab | M20: =IF(AND(ISNUMBER(D20),ISNUMBER(E20)),IF(E20>D20,(E20-D20)*24,""),"") | N20: =IF(AND(ISNUMBER(F20),ISNUMBER(G20)),IF(G20>F20,(G20-F20)*24,""),"") | O20: =IF(J20="X",0,IF(ISNUMBER(H20),H20,IF(ISNUMBER(N20),N20,""))) | P20: =IF(AND(ISNUMBER(H20),ISNUMBER(N20)),H20-N20,"") | Q20: Sabato
A21: 8 | B21: 46061 | C21: dom | M21: =IF(AND(ISNUMBER(D21),ISNUMBER(E21)),IF(E21>D21,(E21-D21)*24,""),"") | N21: =IF(AND(ISNUMBER(F21),ISNUMBER(G21)),IF(G21>F21,(G21-F21)*24,""),"") | O21: =IF(J21="X",0,IF(ISNUMBER(H21),H21,IF(ISNUMBER(N21),N21,""))) | P21: =IF(AND(ISNUMBER(H21),ISNUMBER(N21)),H21-N21,"") | Q21: Domenica
A22: 9 | B22: 46062 | C22: lun | D22: 0.45833333 | E22: 0.58333333 | F22: 0.45833333 | G22: 0.58333333 | H22: 3 | K22: Sì | M22: =IF(AND(ISNUMBER(D22),ISNUMBER(E22)),IF(E22>D22,(E22-D22)*24,""),"") -> 3 | N22: =IF(AND(ISNUMBER(F22),ISNUMBER(G22)),IF(G22>F22,(G22-F22)*24,""),"") -> 3 | O22: =IF(J22="X",0,IF(ISNUMBER(H22),H22,IF(ISNUMBER(N22),N22,""))) -> 3 | P22: =IF(AND(ISNUMBER(H22),ISNUMBER(N22)),H22-N22,"") -> 0 | Q22: OK
A23: 10 | B23: 46063 | C23: mar | D23: 0.45833333 | E23: 0.58333333 | J23: X | L23: 104 | M23: =IF(AND(ISNUMBER(D23),ISNUMBER(E23)),IF(E23>D23,(E23-D23)*24,""),"") -> 3 | N23: =IF(AND(ISNUMBER(F23),ISNUMBER(G23)),IF(G23>F23,(G23-F23)*24,""),"") | O23: =IF(J23="X",0,IF(ISNUMBER(H23),H23,IF(ISNUMBER(N23),N23,""))) -> 0 | P23: =IF(AND(ISNUMBER(H23),ISNUMBER(N23)),H23-N23,"") | Q23: Assenza operatore
A24: 11 | B24: 46064 | C24: mer | M24: =IF(AND(ISNUMBER(D24),ISNUMBER(E24)),IF(E24>D24,(E24-D24)*24,""),"") | N24: =IF(AND(ISNUMBER(F24),ISNUMBER(G24)),IF(G24>F24,(G24-F24)*24,""),"") | O24: =IF(J24="X",0,IF(ISNUMBER(H24),H24,IF(ISNUMBER(N24),N24,""))) | P24: =IF(AND(ISNUMBER(H24),ISNUMBER(N24)),H24-N24,"")
A25: 12 | B25: 46065 | C25: gio | D25: 0.45833333 | E25: 0.58333333 | F25: 0.45833333 | G25: 0.58333333 | H25: 3 | K25: Sì | M25: =IF(AND(ISNUMBER(D25),ISNUMBER(E25)),IF(E25>D25,(E25-D25)*24,""),"") -> 3 | N25: =IF(AND(ISNUMBER(F25),ISNUMBER(G25)),IF(G25>F25,(G25-F25)*24,""),"") -> 3 | O25: =IF(J25="X",0,IF(ISNUMBER(H25),H25,IF(ISNUMBER(N25),N25,""))) -> 3 | P25: =IF(AND(ISNUMBER(H25),ISNUMBER(N25)),H25-N25,"") -> 0 | Q25: OK
A26: 13 | B26: 46066 | C26: ven | D26: 0.45833333 | E26: 0.58333333 | F26: 0.45833333 | G26: 0.58333333 | H26: 3 | K26: Sì | M26: =IF(AND(ISNUMBER(D26),ISNUMBER(E26)),IF(E26>D26,(E26-D26)*24,""),"") -> 3 | N26: =IF(AND(ISNUMBER(F26),ISNUMBER(G26)),IF(G26>F26,(G26-F26)*24,""),"") -> 3 | O26: =IF(J26="X",0,IF(ISNUMBER(H26),H26,IF(ISNUMBER(N26),N26,""))) -> 3 | P26: =IF(AND(ISNUMBER(H26),ISNUMBER(N26)),H26-N26,"") -> 0 | Q26: OK
A27: 14 | B27: 46067 | C27: sab | M27: =IF(AND(ISNUMBER(D27),ISNUMBER(E27)),IF(E27>D27,(E27-D27)*24,""),"") | N27: =IF(AND(ISNUMBER(F27),ISNUMBER(G27)),IF(G27>F27,(G27-F27)*24,""),"") | O27: =IF(J27="X",0,IF(ISNUMBER(H27),H27,IF(ISNUMBER(N27),N27,""))) | P27: =IF(AND(ISNUMBER(H27),ISNUMBER(N27)),H27-N27,"") | Q27: Sabato
A28: 15 | B28: 46068 | C28: dom | M28: =IF(AND(ISNUMBER(D28),ISNUMBER(E28)),IF(E28>D28,(E28-D28)*24,""),"") | N28: =IF(AND(ISNUMBER(F28),ISNUMBER(G28)),IF(G28>F28,(G28-F28)*24,""),"") | O28: =IF(J28="X",0,IF(ISNUMBER(H28),H28,IF(ISNUMBER(N28),N28,""))) | P28: =IF(AND(ISNUMBER(H28),ISNUMBER(N28)),H28-N28,"") | Q28: Domenica
A29: 16 | B29: 46069 | C29: lun | D29: 0.45833333 | E29: 0.58333333 | F29: 0.45833333 | G29: 0.58333333 | H29: 3 | K29: Sì | M29: =IF(AND(ISNUMBER(D29),ISNUMBER(E29)),IF(E29>D29,(E29-D29)*24,""),"") -> 3 | N29: =IF(AND(ISNUMBER(F29),ISNUMBER(G29)),IF(G29>F29,(G29-F29)*24,""),"") -> 3 | O29: =IF(J29="X",0,IF(ISNUMBER(H29),H29,IF(ISNUMBER(N29),N29,""))) -> 3 | P29: =IF(AND(ISNUMBER(H29),ISNUMBER(N29)),H29-N29,"") -> 0 | Q29: OK
A30: 17 | B30: 46070 | C30: mar | D30: 0.45833333 | E30: 0.58333333 | F30: 0.45833333 | G30: 0.58333333 | H30: 3 | K30: Sì | M30: =IF(AND(ISNUMBER(D30),ISNUMBER(E30)),IF(E30>D30,(E30-D30)*24,""),"") -> 3 | N30: =IF(AND(ISNUMBER(F30),ISNUMBER(G30)),IF(G30>F30,(G30-F30)*24,""),"") -> 3 | O30: =IF(J30="X",0,IF(ISNUMBER(H30),H30,IF(ISNUMBER(N30),N30,""))) -> 3 | P30: =IF(AND(ISNUMBER(H30),ISNUMBER(N30)),H30-N30,"") -> 0 | Q30: OK
A31: 18 | B31: 46071 | C31: mer | M31: =IF(AND(ISNUMBER(D31),ISNUMBER(E31)),IF(E31>D31,(E31-D31)*24,""),"") | N31: =IF(AND(ISNUMBER(F31),ISNUMBER(G31)),IF(G31>F31,(G31-F31)*24,""),"") | O31: =IF(J31="X",0,IF(ISNUMBER(H31),H31,IF(ISNUMBER(N31),N31,""))) | P31: =IF(AND(ISNUMBER(H31),ISNUMBER(N31)),H31-N31,"")
A32: 19 | B32: 46072 | C32: gio | D32: 0.45833333 | E32: 0.58333333 | F32: 0.45833333 | G32: 0.58333333 | H32: 3 | K32: Sì | M32: =IF(AND(ISNUMBER(D32),ISNUMBER(E32)),IF(E32>D32,(E32-D32)*24,""),"") -> 3 | N32: =IF(AND(ISNUMBER(F32),ISNUMBER(G32)),IF(G32>F32,(G32-F32)*24,""),"") -> 3 | O32: =IF(J32="X",0,IF(ISNUMBER(H32),H32,IF(ISNUMBER(N32),N32,""))) -> 3 | P32: =IF(AND(ISNUMBER(H32),ISNUMBER(N32)),H32-N32,"") -> 0 | Q32: OK
A33: 20 | B33: 46073 | C33: ven | D33: 0.45833333 | E33: 0.58333333 | F33: 0.45833333 | G33: 0.58333333 | H33: 3 | K33: Sì | M33: =IF(AND(ISNUMBER(D33),ISNUMBER(E33)),IF(E33>D33,(E33-D33)*24,""),"") -> 3 | N33: =IF(AND(ISNUMBER(F33),ISNUMBER(G33)),IF(G33>F33,(G33-F33)*24,""),"") -> 3 | O33: =IF(J33="X",0,IF(ISNUMBER(H33),H33,IF(ISNUMBER(N33),N33,""))) -> 3 | P33: =IF(AND(ISNUMBER(H33),ISNUMBER(N33)),H33-N33,"") -> 0 | Q33: OK
A34: 21 | B34: 46074 | C34: sab | M34: =IF(AND(ISNUMBER(D34),ISNUMBER(E34)),IF(E34>D34,(E34-D34)*24,""),"") | N34: =IF(AND(ISNUMBER(F34),ISNUMBER(G34)),IF(G34>F34,(G34-F34)*24,""),"") | O34: =IF(J34="X",0,IF(ISNUMBER(H34),H34,IF(ISNUMBER(N34),N34,""))) | P34: =IF(AND(ISNUMBER(H34),ISNUMBER(N34)),H34-N34,"") | Q34: Sabato
A35: 22 | B35: 46075 | C35: dom | M35: =IF(AND(ISNUMBER(D35),ISNUMBER(E35)),IF(E35>D35,(E35-D35)*24,""),"") | N35: =IF(AND(ISNUMBER(F35),ISNUMBER(G35)),IF(G35>F35,(G35-F35)*24,""),"") | O35: =IF(J35="X",0,IF(ISNUMBER(H35),H35,IF(ISNUMBER(N35),N35,""))) | P35: =IF(AND(ISNUMBER(H35),ISNUMBER(N35)),H35-N35,"") | Q35: Domenica
A36: 23 | B36: 46076 | C36: lun | D36: 0.45833333 | E36: 0.58333333 | F36: 0.45833333 | G36: 0.58333333 | H36: 3 | K36: Sì | M36: =IF(AND(ISNUMBER(D36),ISNUMBER(E36)),IF(E36>D36,(E36-D36)*24,""),"") -> 3 | N36: =IF(AND(ISNUMBER(F36),ISNUMBER(G36)),IF(G36>F36,(G36-F36)*24,""),"") -> 3 | O36: =IF(J36="X",0,IF(ISNUMBER(H36),H36,IF(ISNUMBER(N36),N36,""))) -> 3 | P36: =IF(AND(ISNUMBER(H36),ISNUMBER(N36)),H36-N36,"") -> 0 | Q36: OK
A37: 24 | B37: 46077 | C37: mar | D37: 0.45833333 | E37: 0.58333333 | F37: 0.45833333 | G37: 0.58333333 | H37: 3 | K37: Sì | M37: =IF(AND(ISNUMBER(D37),ISNUMBER(E37)),IF(E37>D37,(E37-D37)*24,""),"") -> 3 | N37: =IF(AND(ISNUMBER(F37),ISNUMBER(G37)),IF(G37>F37,(G37-F37)*24,""),"") -> 3 | O37: =IF(J37="X",0,IF(ISNUMBER(H37),H37,IF(ISNUMBER(N37),N37,""))) -> 3 | P37: =IF(AND(ISNUMBER(H37),ISNUMBER(N37)),H37-N37,"") -> 0 | Q37: OK
A38: 25 | B38: 46078 | C38: mer | M38: =IF(AND(ISNUMBER(D38),ISNUMBER(E38)),IF(E38>D38,(E38-D38)*24,""),"") | N38: =IF(AND(ISNUMBER(F38),ISNUMBER(G38)),IF(G38>F38,(G38-F38)*24,""),"") | O38: =IF(J38="X",0,IF(ISNUMBER(H38),H38,IF(ISNUMBER(N38),N38,""))) | P38: =IF(AND(ISNUMBER(H38),ISNUMBER(N38)),H38-N38,"")
A39: 26 | B39: 46079 | C39: gio | D39: 0.45833333 | E39: 0.58333333 | F39: 0.45833333 | G39: 0.58333333 | H39: 3 | K39: Sì | M39: =IF(AND(ISNUMBER(D39),ISNUMBER(E39)),IF(E39>D39,(E39-D39)*24,""),"") -> 3 | N39: =IF(AND(ISNUMBER(F39),ISNUMBER(G39)),IF(G39>F39,(G39-F39)*24,""),"") -> 3 | O39: =IF(J39="X",0,IF(ISNUMBER(H39),H39,IF(ISNUMBER(N39),N39,""))) -> 3 | P39: =IF(AND(ISNUMBER(H39),ISNUMBER(N39)),H39-N39,"") -> 0 | Q39: OK
A40: 27 | B40: 46080 | C40: ven | D40: 0.45833333 | E40: 0.58333333 | F40: 0.45833333 | G40: 0.58333333 | H40: 3 | K40: Sì | M40: =IF(AND(ISNUMBER(D40),ISNUMBER(E40)),IF(E40>D40,(E40-D40)*24,""),"") -> 3 | N40: =IF(AND(ISNUMBER(F40),ISNUMBER(G40)),IF(G40>F40,(G40-F40)*24,""),"") -> 3 | O40: =IF(J40="X",0,IF(ISNUMBER(H40),H40,IF(ISNUMBER(N40),N40,""))) -> 3 | P40: =IF(AND(ISNUMBER(H40),ISNUMBER(N40)),H40-N40,"") -> 0 | Q40: OK
A41: 28 | B41: 46081 | C41: sab | M41: =IF(AND(ISNUMBER(D41),ISNUMBER(E41)),IF(E41>D41,(E41-D41)*24,""),"") | N41: =IF(AND(ISNUMBER(F41),ISNUMBER(G41)),IF(G41>F41,(G41-F41)*24,""),"") | O41: =IF(J41="X",0,IF(ISNUMBER(H41),H41,IF(ISNUMBER(N41),N41,""))) | P41: =IF(AND(ISNUMBER(H41),ISNUMBER(N41)),H41-N41,"") | Q41: Sabato
...

Sheet ROSSI M. 02-2026
A1: COMUNE DI NAPOLI · Assistenza Specialistica | Q1: Foglio 3 di 4
A2: Foglio firma mensile · Assistenza Specialistica all'integrazione scolastica destinato agli alunni disabili · Anno scolastico 2025/2026
Q4: ‹ Torna al Riepilogo
A5: Ente | D5: COOPERATIVA SOCIALE SIRIO | I5: Mese/anno di riferimento | L5: 46054 | O5: STATO DEL DOCUMENTO
A6: Istituto scolastico | D6: IC 12 VITTORIO EMANUELE | I6: Ore da PEI (settimanali) | L6: 15 | O6: ERRORI
A7: Operatore | D7: ROSSI MARIO | I7: Sostituzione | L7: No
A8: Alunno | D8: BIANCHI LUCA | I8: Data di compilazione | L8: 46080 | O8: 1 errore · 2 attenzioni · 3 informazioni
A9: Lotto | D9: 1 | I9: Firma coordinatore ente | L9: Presente | O9: 1 campo illeggibile · 2 letture incerte · 0 correzioni manuali
A10: Municipalità | D10: 2 | I10: Timbro referente scolastico | L10: Presente | O10: Non ancora confermato in revisione
M11: Calcoli e controlli di Sirio OCR
A12: Giorno | B12: Data | C12: Gg. | D12: Orario programmato | F12: Orario effettivo | H12: Tot. ore effettive | I12: Assenza alunno | J12: Assenza operatore | K12: Firma operatore | L12: Note | M12: Ore programmate | N12: Ore calcolate | O12: Ore riconosciute | P12: Differenza dich. − calc. | Q12: Esito dei controlli
D13: Entrata | E13: Uscita | F13: Entrata | G13: Uscita
A14: 1 | B14: 46054 | C14: dom | M14: =IF(AND(ISNUMBER(D14),ISNUMBER(E14)),IF(E14>D14,(E14-D14)*24,""),"") | N14: =IF(AND(ISNUMBER(F14),ISNUMBER(G14)),IF(G14>F14,(G14-F14)*24,""),"") | O14: =IF(J14="X",0,IF(ISNUMBER(H14),H14,IF(ISNUMBER(N14),N14,""))) | P14: =IF(AND(ISNUMBER(H14),ISNUMBER(N14)),H14-N14,"") | Q14: Domenica
A15: 2 | B15: 46055 | C15: lun | D15: 0.33333333 | E15: 0.45833333 | F15: 0.33333333 | G15: 0.45833333 | H15: 3 | K15: Sì | M15: =IF(AND(ISNUMBER(D15),ISNUMBER(E15)),IF(E15>D15,(E15-D15)*24,""),"") -> 3 | N15: =IF(AND(ISNUMBER(F15),ISNUMBER(G15)),IF(G15>F15,(G15-F15)*24,""),"") -> 3 | O15: =IF(J15="X",0,IF(ISNUMBER(H15),H15,IF(ISNUMBER(N15),N15,""))) -> 3 | P15: =IF(AND(ISNUMBER(H15),ISNUMBER(N15)),H15-N15,"") -> 0 | Q15: OK
A16: 3 | B16: 46056 | C16: mar | D16: 0.33333333 | E16: 0.45833333 | F16: 0.33333333 | G16: 0.45833333 | H16: 3 | K16: Sì | M16: =IF(AND(ISNUMBER(D16),ISNUMBER(E16)),IF(E16>D16,(E16-D16)*24,""),"") -> 3 | N16: =IF(AND(ISNUMBER(F16),ISNUMBER(G16)),IF(G16>F16,(G16-F16)*24,""),"") -> 3 | O16: =IF(J16="X",0,IF(ISNUMBER(H16),H16,IF(ISNUMBER(N16),N16,""))) -> 3 | P16: =IF(AND(ISNUMBER(H16),ISNUMBER(N16)),H16-N16,"") -> 0 | Q16: OK
A17: 4 | B17: 46057 | C17: mer | D17: 0.33333333 | E17: 0.45833333 | F17: – | G17: – | H17: 1.5 | I17: X | K17: Sì | M17: =IF(AND(ISNUMBER(D17),ISNUMBER(E17)),IF(E17>D17,(E17-D17)*24,""),"") -> 3 | N17: =IF(AND(ISNUMBER(F17),ISNUMBER(G17)),IF(G17>F17,(G17-F17)*24,""),"") | O17: =IF(J17="X",0,IF(ISNUMBER(H17),H17,IF(ISNUMBER(N17),N17,""))) -> 1.5 | P17: =IF(AND(ISNUMBER(H17),ISNUMBER(N17)),H17-N17,"") | Q17: Assenza alunno
A18: 5 | B18: 46058 | C18: gio | D18: 0.33333333 | E18: 0.45833333 | F18: 0.33333333 | G18: 0.45833333 | H18: 3 | K18: Sì | M18: =IF(AND(ISNUMBER(D18),ISNUMBER(E18)),IF(E18>D18,(E18-D18)*24,""),"") -> 3 | N18: =IF(AND(ISNUMBER(F18),ISNUMBER(G18)),IF(G18>F18,(G18-F18)*24,""),"") -> 3 | O18: =IF(J18="X",0,IF(ISNUMBER(H18),H18,IF(ISNUMBER(N18),N18,""))) -> 3 | P18: =IF(AND(ISNUMBER(H18),ISNUMBER(N18)),H18-N18,"") -> 0 | Q18: OK
A19: 6 | B19: 46059 | C19: ven | D19: 0.33333333 | E19: 0.45833333 | F19: 0.33333333 | G19: 0.45833333 | H19: 3 | K19: Sì | M19: =IF(AND(ISNUMBER(D19),ISNUMBER(E19)),IF(E19>D19,(E19-D19)*24,""),"") -> 3 | N19: =IF(AND(ISNUMBER(F19),ISNUMBER(G19)),IF(G19>F19,(G19-F19)*24,""),"") -> 3 | O19: =IF(J19="X",0,IF(ISNUMBER(H19),H19,IF(ISNUMBER(N19),N19,""))) -> 3 | P19: =IF(AND(ISNUMBER(H19),ISNUMBER(N19)),H19-N19,"") -> 0 | Q19: OK
A20: 7 | B20: 46060 | C20: sab | M20: =IF(AND(ISNUMBER(D20),ISNUMBER(E20)),IF(E20>D20,(E20-D20)*24,""),"") | N20: =IF(AND(ISNUMBER(F20),ISNUMBER(G20)),IF(G20>F20,(G20-F20)*24,""),"") | O20: =IF(J20="X",0,IF(ISNUMBER(H20),H20,IF(ISNUMBER(N20),N20,""))) | P20: =IF(AND(ISNUMBER(H20),ISNUMBER(N20)),H20-N20,"") | Q20: Sabato
A21: 8 | B21: 46061 | C21: dom | M21: =IF(AND(ISNUMBER(D21),ISNUMBER(E21)),IF(E21>D21,(E21-D21)*24,""),"") | N21: =IF(AND(ISNUMBER(F21),ISNUMBER(G21)),IF(G21>F21,(G21-F21)*24,""),"") | O21: =IF(J21="X",0,IF(ISNUMBER(H21),H21,IF(ISNUMBER(N21),N21,""))) | P21: =IF(AND(ISNUMBER(H21),ISNUMBER(N21)),H21-N21,"") | Q21: Domenica
A22: 9 | B22: 46062 | C22: lun | D22: 0.33333333 | E22: 0.45833333 | F22: 0.33333333 | G22: 0.45833333 | H22: 3 | K22: Sì | M22: =IF(AND(ISNUMBER(D22),ISNUMBER(E22)),IF(E22>D22,(E22-D22)*24,""),"") -> 3 | N22: =IF(AND(ISNUMBER(F22),ISNUMBER(G22)),IF(G22>F22,(G22-F22)*24,""),"") -> 3 | O22: =IF(J22="X",0,IF(ISNUMBER(H22),H22,IF(ISNUMBER(N22),N22,""))) -> 3 | P22: =IF(AND(ISNUMBER(H22),ISNUMBER(N22)),H22-N22,"") -> 0 | Q22: OK
A23: 10 | B23: 46063 | C23: mar | D23: 0.33333333 | E23: 0.45833333 | F23: 0.33333333 | G23: 0.45833333 | H23: 3 | K23: Sì | M23: =IF(AND(ISNUMBER(D23),ISNUMBER(E23)),IF(E23>D23,(E23-D23)*24,""),"") -> 3 | N23: =IF(AND(ISNUMBER(F23),ISNUMBER(G23)),IF(G23>F23,(G23-F23)*24,""),"") -> 3 | O23: =IF(J23="X",0,IF(ISNUMBER(H23),H23,IF(ISNUMBER(N23),N23,""))) -> 3 | P23: =IF(AND(ISNUMBER(H23),ISNUMBER(N23)),H23-N23,"") -> 0 | Q23: OK
A24: 11 | B24: 46064 | C24: mer | D24: 0.33333333 | E24: 0.45833333 | F24: 0.33333333 | G24: 0.45833333 | H24: 3 | K24: Sì | M24: =IF(AND(ISNUMBER(D24),ISNUMBER(E24)),IF(E24>D24,(E24-D24)*24,""),"") -> 3 | N24: =IF(AND(ISNUMBER(F24),ISNUMBER(G24)),IF(G24>F24,(G24-F24)*24,""),"") -> 3 | O24: =IF(J24="X",0,IF(ISNUMBER(H24),H24,IF(ISNUMBER(N24),N24,""))) -> 3 | P24: =IF(AND(ISNUMBER(H24),ISNUMBER(N24)),H24-N24,"") -> 0 | Q24: OK
A25: 12 | B25: 46065 | C25: gio | D25: 0.33333333 | E25: 0.45833333 | F25: 0.33333333 | G25: ILLEGGIBILE | H25: 3 | K25: Sì | M25: =IF(AND(ISNUMBER(D25),ISNUMBER(E25)),IF(E25>D25,(E25-D25)*24,""),"") -> 3 | N25: =IF(AND(ISNUMBER(F25),ISNUMBER(G25)),IF(G25>F25,(G25-F25)*24,""),"") | O25: =IF(J25="X",0,IF(ISNUMBER(H25),H25,IF(ISNUMBER(N25),N25,""))) -> 3 | P25: =IF(AND(ISNUMBER(H25),ISNUMBER(N25)),H25-N25,"") | Q25: Errore – illeggibile: uscita effettiva
A26: 13 | B26: 46066 | C26: ven | D26: 0.33333333 | E26: 0.45833333 | F26: 0.33333333 | G26: 0.45833333 | H26: 3 | K26: Sì | M26: =IF(AND(ISNUMBER(D26),ISNUMBER(E26)),IF(E26>D26,(E26-D26)*24,""),"") -> 3 | N26: =IF(AND(ISNUMBER(F26),ISNUMBER(G26)),IF(G26>F26,(G26-F26)*24,""),"") -> 3 | O26: =IF(J26="X",0,IF(ISNUMBER(H26),H26,IF(ISNUMBER(N26),N26,""))) -> 3 | P26: =IF(AND(ISNUMBER(H26),ISNUMBER(N26)),H26-N26,"") -> 0 | Q26: OK
A27: 14 | B27: 46067 | C27: sab | M27: =IF(AND(ISNUMBER(D27),ISNUMBER(E27)),IF(E27>D27,(E27-D27)*24,""),"") | N27: =IF(AND(ISNUMBER(F27),ISNUMBER(G27)),IF(G27>F27,(G27-F27)*24,""),"") | O27: =IF(J27="X",0,IF(ISNUMBER(H27),H27,IF(ISNUMBER(N27),N27,""))) | P27: =IF(AND(ISNUMBER(H27),ISNUMBER(N27)),H27-N27,"") | Q27: Sabato
A28: 15 | B28: 46068 | C28: dom | M28: =IF(AND(ISNUMBER(D28),ISNUMBER(E28)),IF(E28>D28,(E28-D28)*24,""),"") | N28: =IF(AND(ISNUMBER(F28),ISNUMBER(G28)),IF(G28>F28,(G28-F28)*24,""),"") | O28: =IF(J28="X",0,IF(ISNUMBER(H28),H28,IF(ISNUMBER(N28),N28,""))) | P28: =IF(AND(ISNUMBER(H28),ISNUMBER(N28)),H28-N28,"") | Q28: Domenica
A29: 16 | B29: 46069 | C29: lun | D29: 0.33333333 | E29: 0.45833333 | F29: – | G29: – | L29: PONTE DI CARNEVALE | M29: =IF(AND(ISNUMBER(D29),ISNUMBER(E29)),IF(E29>D29,(E29-D29)*24,""),"") -> 3 | N29: =IF(AND(ISNUMBER(F29),ISNUMBER(G29)),IF(G29>F29,(G29-F29)*24,""),"") | O29: =IF(J29="X",0,IF(ISNUMBER(H29),H29,IF(ISNUMBER(N29),N29,""))) | P29: =IF(AND(ISNUMBER(H29),ISNUMBER(N29)),H29-N29,"") | Q29: Non svolto
A30: 17 | B30: 46070 | C30: mar | D30: 0.33333333 | E30: 0.45833333 | F30: – | G30: – | L30: PONTE DI CARNEVALE | M30: =IF(AND(ISNUMBER(D30),ISNUMBER(E30)),IF(E30>D30,(E30-D30)*24,""),"") -> 3 | N30: =IF(AND(ISNUMBER(F30),ISNUMBER(G30)),IF(G30>F30,(G30-F30)*24,""),"") | O30: =IF(J30="X",0,IF(ISNUMBER(H30),H30,IF(ISNUMBER(N30),N30,""))) | P30: =IF(AND(ISNUMBER(H30),ISNUMBER(N30)),H30-N30,"") | Q30: Non svolto
A31: 18 | B31: 46071 | C31: mer | D31: 0.33333333 | E31: 0.45833333 | F31: 0.33333333 | G31: 0.45833333 | H31: 3 | K31: Sì | M31: =IF(AND(ISNUMBER(D31),ISNUMBER(E31)),IF(E31>D31,(E31-D31)*24,""),"") -> 3 | N31: =IF(AND(ISNUMBER(F31),ISNUMBER(G31)),IF(G31>F31,(G31-F31)*24,""),"") -> 3 | O31: =IF(J31="X",0,IF(ISNUMBER(H31),H31,IF(ISNUMBER(N31),N31,""))) -> 3 | P31: =IF(AND(ISNUMBER(H31),ISNUMBER(N31)),H31-N31,"") -> 0 | Q31: Da verificare – lettura incerta: tot. ore effettive
A32: 19 | B32: 46072 | C32: gio | D32: 0.33333333 | E32: 0.45833333 | F32: 0.33333333 | G32: 0.45833333 | H32: 3 | K32: Sì | M32: =IF(AND(ISNUMBER(D32),ISNUMBER(E32)),IF(E32>D32,(E32-D32)*24,""),"") -> 3 | N32: =IF(AND(ISNUMBER(F32),ISNUMBER(G32)),IF(G32>F32,(G32-F32)*24,""),"") -> 3 | O32: =IF(J32="X",0,IF(ISNUMBER(H32),H32,IF(ISNUMBER(N32),N32,""))) -> 3 | P32: =IF(AND(ISNUMBER(H32),ISNUMBER(N32)),H32-N32,"") -> 0 | Q32: OK
A33: 20 | B33: 46073 | C33: ven | D33: 0.33333333 | E33: 0.45833333 | F33: 0.33333333 | G33: 0.45833333 | H33: 3 | K33: Sì | M33: =IF(AND(ISNUMBER(D33),ISNUMBER(E33)),IF(E33>D33,(E33-D33)*24,""),"") -> 3 | N33: =IF(AND(ISNUMBER(F33),ISNUMBER(G33)),IF(G33>F33,(G33-F33)*24,""),"") -> 3 | O33: =IF(J33="X",0,IF(ISNUMBER(H33),H33,IF(ISNUMBER(N33),N33,""))) -> 3 | P33: =IF(AND(ISNUMBER(H33),ISNUMBER(N33)),H33-N33,"") -> 0 | Q33: OK
A34: 21 | B34: 46074 | C34: sab | M34: =IF(AND(ISNUMBER(D34),ISNUMBER(E34)),IF(E34>D34,(E34-D34)*24,""),"") | N34: =IF(AND(ISNUMBER(F34),ISNUMBER(G34)),IF(G34>F34,(G34-F34)*24,""),"") | O34: =IF(J34="X",0,IF(ISNUMBER(H34),H34,IF(ISNUMBER(N34),N34,""))) | P34: =IF(AND(ISNUMBER(H34),ISNUMBER(N34)),H34-N34,"") | Q34: Sabato
A35: 22 | B35: 46075 | C35: dom | M35: =IF(AND(ISNUMBER(D35),ISNUMBER(E35)),IF(E35>D35,(E35-D35)*24,""),"") | N35: =IF(AND(ISNUMBER(F35),ISNUMBER(G35)),IF(G35>F35,(G35-F35)*24,""),"") | O35: =IF(J35="X",0,IF(ISNUMBER(H35),H35,IF(ISNUMBER(N35),N35,""))) | P35: =IF(AND(ISNUMBER(H35),ISNUMBER(N35)),H35-N35,"") | Q35: Domenica
